Workbook

Sheet Balance
B1: Dry biomass | D1: Basis (dry biomass): | E1: 3500 | F1: tpa
B2: mass %
A3: Hemicellulose | B3: 30 | E3: Dry biomass | F3: Fermenter feedstock | G3: Fibers as biofillers | H3: PHA copolymers | I3: CHP feedstock | J3: PHA-biocomposite
A4: Cellulose | B4: 46 | E4: =F1 -> tpa | F4: =F1 -> tpa | G4: =F1 -> tpa | H4: =F1 -> tpa | I4: =F1 -> tpa | J4: =F1 -> tpa
A5: Lignin | B5: 20 | D5: Hemicellulose | E5: =B3/100*$E$1 -> 1050 | F5: =E5*B11 -> 997.5
A6: Ash | B6: 4 | D6: Cellulose | E6: =B4/100*$E$1 -> 1610 | F6: =E6*B12 -> 1400.7 | G6: =E6-F6 -> 209.3
D7: Lignin | E7: =B5/100*$E$1 -> 700 | F7: =E7*B13 -> 553
A8: Mass % moisture in wet biomass | B8: 76 | D8: Ash | E8: =B6/100*$E$1 -> 140
A10: Recovery rate to fermenter | D10: PHA copolymers | H10: =(F5+F6)*B14 -> 839.37
A11: Hemicellulose | B11: 0.95
A12: Cellulose | B12: 0.87 | D12: CHP feedstock | I12: =E7+F5+F6-G6-H10 -> 2049.53
A13: Lignin | B13: 0.79 | D13: PHA-biocomposite | J13: =(H10+G6)*B15/100 -> 999.99074
A14: PHA copolymer | B14: 0.35 | D14: Total - Ash | E14: =SUM(E5:E7) -> 3360 | F14: =SUM(F5:F7) -> 2951.2 | G14: =SUM(G5:G7) -> 209.3 | H14: =H10 -> 839.37 | I14: =I12 -> 2049.53 | J14: =J13 -> 999.99074
A15: Final biocomposite recovery | B15: 95.358
A17: Calorific value | B17: 20 | C17: GJ/t | D17: Electricity generation | E17: =I12*B17*B18 -> 14346.71 | F17: GJ
A18: Electrical efficiency | B18: 0.35 | D18: Electricity consumption by the process | E18: 2.6 | F18: MWh/t (biofiller + copolymer)

Sheet TEA
A1: For any material and concept use Cite: ©Sadhukhan J, Ng KS, Martinez-Hernandez E. 2014. Biorefineries and Chemical Processes: Design, Integration and Sustainability Analysis. Wiley. https://onlinelibrary.wiley.com/doi/book/10.1002/9781118698129
A2: Capital cost estimation | B2: Production rate | C2: =Balance!E1 -> 3500 | D2: tpa | E2: Operating days | F2: 290 | G2: per year | H2: Current CEPCI | I2: 820
A3: Unit | B3: Base cost, million $ | C3: Scale factor | D3: Base size | E3: Unit | F3: CEPCI-Base year | G3: Current size | H3: Current costs, million $
A4: Inoculation | B4: 0.26 | C4: 0.6 | D4: 3.53 | E4: tph | F4: 402 | G4: =(Balance!F14+Balance!E8)/TEA!F2/24 -> 0.44413793 | H4: =B4*(G4/D4)^C4*$I$2/F4 -> 0.15289984
A5: Fermenters | B5: 0.67 | C5: 0.8 | D5: 1.04 | E5: tph | F5: 402 | G5: =G4 -> 0.44413793 | H5: =B5*(G5/D5)^C5*$I$2/F5 -> 0.69191098
A6: Centrifugation | B6: 2.92 | C6: 0.7 | D6: 18.466 | E6: tph | F6: 402 | G6: =G5 -> 0.44413793 | H6: =B6*(G6/D6)^C6*$I$2/F6 -> 0.43830071
A7: Solvent extraction-recovery | B7: 2.96 | C7: 0.7 | D7: 18.466 | E7: tph | F7: 402 | G7: =G4 -> 0.44413793 | H7: =B7*(G7/D7)^C7*$I$2/F7 -> 0.44430483
A8: Washing | B8: 0.41 | C8: 1 | D8: 33.5 | E8: tph | F8: 394.3 | G8: =G4 -> 0.44413793 | H8: =B8*(G8/D8)^C8*$I$2/F8 -> 0.011304308
A9: Drying | B9: 7.6 | C9: 0.8 | D9: 33.5 | E9: tph | F9: 394.3 | G9: =G4 -> 0.44413793 | H9: =B9*(G9/D9)^C9*$I$2/F9 -> 0.497484
A10: Anaerobic digestion | B10: 1.54 | C10: 0.6 | D10: 43 | E10: tph wastewater | F10: 402 | G10: =(Balance!E1/((100-Balance!B8)/100)*(Balance!B8/100))/TEA!F2/24+Balance!I14/TEA!F2/24 -> 1.8869057 | H10: =B10*(G10/D10)^C10*$I$2/F10 -> 0.48136838
A11: CHP | B11: 1 | C11: 1 | D11: 5 | E11: GWh | F11: =I2 -> 820 | G11: =Balance!E17/1000/3.6 -> 3.9851972 | H11: =B11*(G11/D11)^C11*$I$2/F11 -> 0.79703944
A12: Biomass handling | B12: 14.1 | C12: 0.78 | D12: 83.3 | E12: tph wet biomass | F12: 402 | G12: =(Balance!E1/((100-Balance!B8)/100))/TEA!F2/24 -> 2.0953065 | H12: =B12*(G12/D12)^C12*$I$2/F12 -> 1.6265856
A13: Biomass pretreatment | B13: 5.62 | C13: 0.78 | D13: 83.3 | E13: tph dry biomass | F13: 402 | G13: =(Balance!E14+Balance!E8)/TEA!F2/24 -> 0.50287356 | H13: =B13*(G13/D13)^C13*$I$2/F13 -> 0.21298984
A14: Twin-screw extrusion | B14: 0.077922078 | C14: 1 | D14: 1 | E14: tph | F14: =I2 -> 820 | G14: =(Balance!G14+Balance!H14)/TEA!F2/24 -> 0.15067098 | H14: =B14*(G14/D14)^C14*$I$2/F14 -> 0.011740596
A15: Injection moulding | B15: 0.1038961 | C15: 1 | D15: 1 | E15: tph | F15: =I2 -> 820 | G15: =G14 -> 0.15067098 | H15: =B15*(G15/D15)^C15*$I$2/F15 -> 0.015654127
A16: 3d printing | B16: 0.077922078 | C16: 1 | D16: 1 | E16: tph | F16: =I2 -> 820 | G16: =G14 -> 0.15067098 | H16: =B16*(G16/D16)^C16*$I$2/F16 -> 0.011740596
A17: Delivered cost of equipment | H17: =SUM(H4:H16) -> 5.3933232
A18: Total capital investment | H18: =F31*H17 -> 16.17997
A20: Opex parameters | B20: Quantity | C20: Unit | D20: Price | E20: Unit | F20: Variable opex, million $/y | G20: Product value million $/y
A21: Reagents | B21: =(SUM(GWP!B2:B3)+SUM(GWP!B5:B7)+SUM(GWP!B9:B16))*(Balance!G14+Balance!H14) -> 1215.1736 | C21: =Balance!F1 -> tpa | D21: 0.26 | E21: $/kg | F21: =B21*D21/1000 -> 0.31594514
A22: Electricity | B22: =-Balance!E17/1000+Balance!E18*(Balance!G14+Balance!H14)*3.6/1000 -> -4.5311588 | C22: TJ/y | D22: 1.2319481 | E22: $/MJ | F22: =B22*D22 -> -5.5821523
A23: Heat | B23: =GWP!B4*Balance!J14/1000 -> 2.1999796 | C23: TJ/y | D23: 0.29407792 | E23: $/MJ | F23: =B23*D23 -> 0.64696544
A24: Annual capital charge | B24: 0.1
A25: Internal rate on return | B25: 0.1
A26: Labor cost | D26: 85000 | E26: $/y
A27: Number of jobs | B27: 23 | C27: per kt biocomposites
A28: Lignocellulose biomass | B28: =Balance!E1 -> 3500 | C28: tpa | D28: 100 | E28: $/dry t | F28: =B28*D28/1000000 -> 0.35
A29: PHA biocomposite | B29: =Balance!J14 -> 999.99074 | C29: tpa | D29: 7 | E29: $/kg | G29: =B29*D29/1000 -> 6.9999352
B31: million $/y | E31: Total capital investment/Delivered cost of equipment | F31: 3
A32: Capex | B32: =H18*B24 -> 1.617997 | E32: Indirect cost-dependent fixed Opex/Capex | F32: 0.06
A33: Indirect cost-dependent fixed Opex | B33: =B32*F32 -> 0.097079818
A34: Labor cost-dependent fixed Opex | B34: =B27*Balance!J14/1000*D26/1000000*1.9 -> 3.7144656 | E34: Discounted cash flow analysis
A35: Variable Opex | B35: =SUM(F21:F23) -> -4.6192417 | E35: year | F35: Cash flow million $/y | G35: Net present value million $/y
A36: Feedstock cost | B36: =F28 -> 0.35 | E36: 0 | F36: =-H18 -> -16.17997 | G36: =F36 -> -16.17997
A37: Miscellaneous Opex | B37: =0.3*(B33+B34+F21+F23) -> 1.4323368 | E37: 1 | F37: =$B$41/(1+$B$25)^E37 -> 4.0066342 | G37: =G36+F37 -> -12.173335
A38: Opex | B38: =SUM(B33:B37) -> 0.97464054 | E38: 2 | F38: =$B$41/(1+$B$25)^E38 -> 3.6423948 | G38: =G37+F38 -> -8.5309406
A39: Total cost (Capex+Opex) | B39: =B32+B38 -> 2.5926375 | E39: 3 | F39: =$B$41/(1+$B$25)^E39 -> 3.311268 | G39: =G38+F39 -> -5.2196726
A40: Product value | B40: =G29 -> 6.9999352 | E40: 4 | F40: =$B$41/(1+$B$25)^E40 -> 3.0102436 | G40: =G39+F40 -> -2.209429
A41: Product value - total cost | B41: =B40-B39 -> 4.4072977 | E41: 5 | F41: =$B$41/(1+$B$25)^E41 -> 2.7365851 | G41: =G40+F41 -> 0.52715611
E42: 6 | F42: =$B$41/(1+$B$25)^E42 -> 2.4878046 | G42: =G41+F42 -> 3.0149607
...

Sheet GWP
A1: Inventory | B1: Flow per kg biocomposite | C1: Unit | D1: GWP kg CO2e | E1: Unit | F1: GWP kg CO2e/kg biocomposite
A2: Sodium hydroxide | B2: 0.4 | C2: kg | D2: 1.3132269 | E2: per kg | F2: =B2*D2 -> 0.52529076
A3: Sodium phosphate | B3: 0.145 | C3: kg | D3: 2.8194834 | E3: per kg | F3: =B3*D3 -> 0.4088251
A4: Process steam | B4: 2.2 | C4: MJ | D4: 0.071211959 | E4: per MJ | F4: =B4*D4 -> 0.15666631
A5: Monoammonium phosphate | B5: 0.115 | C5: kg | D5: 0.91979965 | E5: per kg | F5: =B5*D5 -> 0.10577696
A6: Solvent | B6: 0.1 | C6: kg | D6: 0.85517497 | E6: per kg | F6: =B6*D6 -> 0.085517497
A7: Ammonium chloride | B7: 0.05 | C7: kg | D7: 1.601479 | E7: per kg | F7: =B7*D7 -> 0.080073948
A8: Transport | B8: 100 | C8: ktkm | D8: 0.00054090589 | E8: per ktkm | F8: =B8*D8 -> 0.054090589
A9: Magnesium sulphate | B9: 0.025 | C9: kg | D9: 1.3539983 | E9: per kg | F9: =B9*D9 -> 0.033849958
A10: Sulfuric acid | B10: 0.2 | C10: kg | D10: 0.16709785 | E10: per kg | F10: =B10*D10 -> 0.033419571
A11: Citric acid | B11: 0.0025 | C11: kg | D11: 6.1545092 | E11: per kg | F11: =B11*D11 -> 0.015386273
A12: Lime | B12: 0.01 | C12: kg | D12: 0.92369312 | E12: per kg | F12: =B12*D12 -> 0.0092369312
A13: Manganese | B13: 0.00025 | C13: kg | D13: 5.5776652 | E13: per kg | F13: =B13*D13 -> 0.0013944163
... A16: Water | B16: 0.11 | C16: kg | D16: 0.00048755765 | E16: per kg | F16: =B16*D16 -> 5.3631342e-05
F17: =SUM(F2:F16) -> 1.5110753
